Workbook

Sheet Cover Page
B3: TVS MOTOR COMPANY LIMITED
B5: Sum-of-the-parts equity valuation | DCF · Relative · Precedent transactions · Asset-based | NSE: TVSMOTOR
B9: THE COMPANY
B10: India's third-largest two-wheeler manufacturer and second-largest 2W exporter; the only domestic OEM present across motorcycles, scooters and mopeds, plus three-wheelers. Brands: Apache, Raider, Ronin, Jupiter, NTorq, iQube and Orbiter. The group also owns Norton Motorcycles (UK), 85.15% of the NBFC TVS Credit Services, and manufacturing in Indonesia. FY26 standalone revenue ₹47,270 cr on 58.9 lakh units.
B13: WHY SUM-OF-THE-PARTS
B14: Consolidated accounts blend a capital-light manufacturer with a balance-sheet-intensive lender. Of the ₹32,791 cr of FY26 consolidated borrowings, the bulk funds TVS Credit's ₹30,639 cr loan book — an operating input for an NBFC, not leverage on the OEM. Consolidating distorts WACC, working capital and margin at once. The core automotive business is therefore valued on standalone financials via FCFF, TVS Credit on NBFC-appropriate P/B and excess-return methods, and the remaining strategic subsidiaries at appraised value. The three legs aggregate to an implied equity value per share.
B18: CONTENTS
B19: 1 | C19: Balance Sheet | E19: 10 | F19: DCF - FCFE & DDM
B20: 2 | C20: Income Statement | E20: 11 | F20: TVS Credit (NBFC)
B21: 3 | C21: Cash Flows | E21: 12 | F21: Peer Comps
B22: 4 | C22: Graphical Representation | E22: 13 | F22: Precedent Transactions
B23: 5 | C23: Guidance & Assumptions | E23: 14 | F23: Asset-Based Valuation
B24: 6 | C24: Revenue Segments | E24: 15 | F24: SOTP & Football Field
B25: 7 | C25: Cost Structure & Hedging | E25: 16 | F25: Sensitivity & Scenarios
B26: 8 | C26: Debt & Cost of Capital | E26: 17 | F26: Monte Carlo
B27: 9 | C27: DCF - FCFF | E27: 18 | F27: Credit & Quality Analysis
B29: FORMATTING KEY
B30: ■ | C30: Reported actuals / hardcoded data | F30: ■ | G30: Amber fill — key valuation lever
B31: ■ | C31: Formulas and cross-sheet links
B32: ■ | C32: Forecast drivers — flex these | F32: Chart colour coding
B33: ■ | C33: Checks, flags and reconciliations | F33: ■ Motorcycles
F34: ■ Scooters - ICE
F35: ■ Electric 2W
B36: MODEL INFORMATION
B37: Author | D37: Niranjan Desai
B38: Valuation date | D38: 46246
B39: Entity valued | D39: TVS Motor Company Ltd (NSE: TVSMOTOR | BSE: 532343) — group, via SOTP
B40: Forecast horizon | D40: FY2027E–FY2031E explicit; Gordon Growth terminal value, cross-checked on exit multiple
B41: Reporting basis | D41: Core automotive on standalone financials; TVS Credit and other subsidiaries valued separately
B42: Discounting convention | D42: Cash flows discounted from 12 Aug 2026. FY27E is stub-adjusted to the 231 days falling after the valuation date, and net debt is rolled forward to 12 Aug 2026 — see section D of the DCF tab.
B43: Equity risk premium | D43: Damodaran India total ERP, 7.08%. No separate country premium is added on top.
B44: Half-yearly basis | D44: Revenue Segments and Income Statement are built H1/H2/FY. FY24–FY26 halves come from reported quarters; FY22–FY23 halves are apportioned at the FY24–FY26 average H1 share. Full-year columns are audited.
B45: Purpose | D45: Business Valuation group project, MBA Trimester IV, SBM-NMIMS
B46: Disclaimer | D46: Academic and illustrative only. Not investment advice.
B48: PRIMARY SOURCES
B49: • | C49: Audited standalone and consolidated financials FY22–FY26 — BSE XBRL filings via Screener.in (12 Aug 2026)
B50: • | C50: Volumes — TVS Motor monthly and annual sales releases filed with BSE/NSE
B51: • | C51: TVS Credit Services — results releases; TVS Motor BSE Reg-30 disclosure, 27 Jul 2026 (stake, net worth, PAT)
B52: • | C52: Debt — BSE Reg-30 NCD allotment 10 Aug 2026 (₹1,000 cr at 7.28%, maturity 10 Nov 2029); NCRPS redemption 11 Aug 2026
B53: • | C53: Ratings — CARE rationales 3 Jul and 23 Jul 2026; ICRA rationale for TVS Credit Services
...

Sheet Control Panel
B1: TVS MOTOR COMPANY LIMITED
B2: Fiscal year ending 31 March
B3: Every switch below re-drives the whole model. Change the blue cells only — the lookup tables underneath feed them.
B5: A. SCENARIO SWITCHES
B6: Control | C6: Selection | O6: What it drives
B7: Operating case | C7: Base | O7: Raw material and capex as a % of sales, and a multiplier on every segment volume growth rate
B8: Terminal growth case | C8: Base | O8: Terminal growth g on the Debt & Cost of Capital tab — flows into the DCF, FCFE, DDM and every sensitivity table
B9: Beta basis | C9: Average of both | O9: Which beta feeds the CAPM: the raw regression, the Hamada-relevered bottom-up, or the average
B10: WACC adjustment | C10: As calculated | O10: A manual overlay on the computed WACC for stress testing without touching the CAPM build
B11: Commodity pass-through | C11: Base - 70% | O11: Share of a raw-material price move recovered in vehicle pricing — drives the commodity sensitivity on the Cost tab
B12: TVS Credit valuation method | C12: Average of three | O12: Which of the three NBFC methods sets Leg 2 of the sum-of-the-parts
B13: Peer multiple basis | C13: Peer median | O13: Which point of the peer multiple range drives the relative valuation
B14: SOTP weighting scheme | C14: Balanced | O14: The weights applied to the seven methodologies in the concluded value
B15: Monte Carlo volatility regime | C15: Base | O15: Scales all four input standard deviations in the simulation
B17: B. LIVE OUTPUT — UPDATES AS YOU SWITCH
B18: Cost of equity Ke | C18: ='Debt & Cost of Capital'!C45 -> 0.1390553
B19: WACC | C19: ='Debt & Cost of Capital'!C57 -> 0.13755226
B20: Terminal growth g | C20: ='Debt & Cost of Capital'!C64 -> 0.055
B21: Core automotive value per share (₹) | C21: ='DCF - FCFF'!C75 -> 1774.9018
B22: TVS Credit per TVS Motor share (₹) | C22: ='TVS Credit (NBFC)'!C57 -> 226.87519
B23: SOTP value per share (₹) | C23: ='SOTP & Football Field'!C24 -> 2079.6575
B24: CONCLUDED VALUE PER SHARE (₹) | C24: ='SOTP & Football Field'!C50 -> 2615.7926
B25: Current market price (₹) | C25: ='Debt & Cost of Capital'!C48 -> 4343
B26: Upside / (downside) | C26: ='SOTP & Football Field'!C52 -> -0.39769914
B27: Implied recommendation | C27: ='SOTP & Football Field'!C53 -> SELL
B29: C. LOOKUP TABLES (feed the switches above — edit values here, not the switch)
B30: Operating case | C30: RM % FY27E | D30: FY28E | E30: FY29E | F30: FY30E | G30: FY31E | H30: Capex % FY27E | I30: FY28E | J30: FY29E | K30: FY30E | L30: FY31E | M30: Volume growth ×
B31: Conservative | C31: 0.72 | D31: 0.719 | E31: 0.718 | F31: 0.717 | G31: 0.716 | H31: 0.045 | I31: 0.043 | J31: 0.041 | K31: 0.039 | L31: 0.038 | M31: 0.7
B32: Base | C32: 0.712 | D32: 0.708 | E32: 0.705 | F32: 0.703 | G32: 0.701 | H32: 0.042 | I32: 0.04 | J32: 0.038 | K32: 0.036 | L32: 0.035 | M32: 1
B33: Aggressive | C33: 0.704 | D33: 0.697 | E33: 0.692 | F33: 0.688 | G33: 0.685 | H33: 0.04 | I33: 0.038 | J33: 0.036 | K33: 0.034 | L33: 0.033 | M33: 1.25
B35: Terminal growth case | C35: g
B36: Conservative | C36: 0.045
B37: Base | C37: 0.055
B38: Aggressive | C38: 0.06
B40: WACC adjustment | C40: Overlay
B41: -100 bp | C41: -0.01
B42: -50 bp | C42: -0.005
B43: As calculated | C43: 0
B44: +50 bp | C44: 0.005
B45: +100 bp | C45: 0.01
...

Sheet Balance Sheet
B1: TVS MOTOR COMPANY LIMITED
B2: Fiscal year ending 31 March | C2: Actual | D2: Actual | E2: Actual | F2: Actual | G2: Actual | H2: Estimate | I2: Estimate | J2: Estimate | K2: Estimate | L2: Estimate
B3: All amounts in ₹ crores unless stated · Standalone (core automotive) | C3: FY2022 | D3: FY2023 | E3: FY2024 | F3: FY2025 | G3: FY2026 | H3: FY2027E | I3: FY2028E | J3: FY2029E | K3: FY2030E | L3: FY2031E
B5: BALANCE SHEET
B7: EQUITY & LIABILITIES
B8: Equity share capital | C8: 48 | D8: 48 | E8: 48 | F8: 48 | G8: 48 | H8: =G8 -> 48 | I8: =H8 -> 48 | J8: =I8 -> 48 | K8: =J8 -> 48 | L8: =K8 -> 48
B9: Other equity (reserves & surplus) | C9: 4775 | D9: 6000 | E9: 7684 | F9: 9850 | G9: 11187 | H9: =G9+'Income Statement'!T36-'Income Statement'!T45 -> 15333.008 | I9: =H9+'Income Statement'!W36-'Income Statement'!W45 -> 20387.494 | J9: =I9+'Income Statement'!Z36-'Income Statement'!Z45 -> 26292.48 | K9: =J9+'Income Statement'!AC36-'Income Statement'!AC45 -> 32990.346 | L9: =K9+'Income Statement'!AF36-'Income Statement'!AF45 -> 40502.786
B11: TOTAL SHAREHOLDERS' EQUITY | C11: =C8+C9 -> 4823 | D11: =D8+D9 -> 6048 | E11: =E8+E9 -> 7732 | F11: =F8+F9 -> 9898 | G11: =G8+G9 -> 11235 | H11: =H8+H9 -> 15381.008 | I11: =I8+I9 -> 20435.494 | J11: =J8+J9 -> 26340.48 | ... L11: =L8+L9 -> 40550.786
B13: Total borrowings | C13: 1963 | D13: 2663 | E13: 1964 | F13: 2037 | G13: 3733 | H13: =H53 -> 3733 | I13: =I53 -> 3733 | J13: =J53 -> 3733 | K13: =K53 -> 3733 | L13: =L53 -> 3733
B14: Trade payables | C14: =C38*'Income Statement'!E10/365 -> 3946.5123 | D14: =D38*'Income Statement'!H10/365 -> 4010.9589 | E14: =E38*'Income Statement'!K10/365 -> 5077.2603 | F14: =F38*'Income Statement'!N10/365 -> 6212.5151 | G14: =G38*'Income Statement'!Q10/365 -> 8345.3425 | H14: =H38*'Income Statement'!T10/365 -> 10312.052 | I14: =I38*'Income Statement'!W10/365 -> 12212.338 | J14: =J38*'Income Statement'!Z10/365 -> 14049.197 | K14: =K38*'Income Statement'!AC10/365 -> 15861.763 | L14: =L38*'Income Statement'!AF10/365 -> 17701.86
B15: Other liabilities & provisions | C15: =C16-C14 -> 1171.4877 | D15: =D16-D14 -> 1270.0411 | E15: =E16-E14 -> 1290.7397 | F15: =F16-F14 -> 1804.4849 | G15: =G16-G14 -> 2602.6575 | H15: =G15/'Income Statement'!Q7*'Income Statement'!T7 -> 3234.051 | I15: =H15/'Income Statement'!T7*'Income Statement'!W7 -> 3851.6545 | J15: =I15/'Income Statement'!W7*'Income Statement'!Z7 -> 4449.8376 | K15: =J15/'Income Statement'!Z7*'Income Statement'!AC7 -> 5038.2291 | L15: =K15/'Income Statement'!AC7*'Income Statement'!AF7 -> 5638.7478
B16: Total other liabilities | C16: 5118 | D16: 5281 | E16: 6368 | F16: 8017 | G16: 10948 | H16: =H14+H15 -> 13546.103 | I16: =I14+I15 -> 16063.992 | J16: =J14+J15 -> 18499.035 | K16: =K14+K15 -> 20899.992 | L16: =L14+L15 -> 23340.608
B17: TOTAL EQUITY & LIABILITIES | C17: =C11+C13+C16 -> 11904 | D17: =D11+D13+D16 -> 13992 | E17: =E11+E13+E16 -> 16064 | F17: =F11+F13+F16 -> 19952 | G17: =G11+G13+G16 -> 25916 | H17: =H11+H13+H16 -> 32660.111 | I17: =I11+I13+I16 -> 40232.486 | J17: =J11+J13+J16 -> 48572.515 | ... L17: =L11+L13+L16 -> 67624.394
B19: ASSETS
B20: Property, plant & equipment (net block) | C20: 3307 | D20: 3596 | E20: 3772 | F20: 4402 | G20: 5460 | H20: =H47-H21 -> 7084.7049 | I20: =I47-I21 -> 8839.9654 | J20: =J47-J21 -> 10651.387 | K20: =K47-K21 -> 12462.173 | L20: =L47-L21 -> 14339.558
B21: Capital work-in-progress | C21: 424 | D21: 628 | E21: 930 | F21: 1239 | G21: 1360 | H21: =G21 -> 1360 | I21: =H21 -> 1360 | J21: =I21 -> 1360 | K21: =J21 -> 1360 | L21: =K21 -> 1360
B22: Investments — total | C22: 4716 | D22: 5684 | E22: 6991 | F22: 9163 | G22: 11647 | H22: =H23+H24 -> 11647 | I22: =I23+I24 -> 11647 | J22: =J23+J24 -> 11647 | K22: =K23+K24 -> 11647 | L22: =L23+L24 -> 11647
B23: of which: investments in subsidiaries, JVs & associates | C23: 4100 | D23: 5000 | E23: 6250 | F23: 8300 | G23: 10650 | H23: =G23 -> 10650 | I23: =H23 -> 10650 | J23: =I23 -> 10650 | K23: =J23 -> 10650 | L23: =K23 -> 10650
B24: of which: treasury & liquid investments | C24: =C22-C23 -> 616 | D24: =D22-D23 -> 684 | E24: =E22-E23 -> 741 | F24: =F22-F23 -> 863 | G24: =G22-G23 -> 997 | H24: =G24 -> 997 | I24: =H24 -> 997 | J24: =I24 -> 997 | K24: =J24 -> 997 | L24: =K24 -> 997
B26: Inventories | C26: =C36*'Income Statement'!E10/365 -> 1103.326 | D26: =D36*'Income Statement'!H10/365 -> 1230.0274 | E26: =E36*'Income Statement'!K10/365 -> 1332.7808 | F26: =F36*'Income Statement'!N10/365 -> 1713.7973 | G26: =G36*'Income Statement'!Q10/365 -> 1576.3425 | H26: =H36*'Income Statement'!T10/365 -> 1947.832 | I26: =I36*'Income Statement'!W10/365 -> 2306.7749 | J26: =J36*'Income Statement'!Z10/365 -> 2653.7372 | K26: =K36*'Income Statement'!AC10/365 -> 2996.1108 | L26: =L36*'Income Statement'!AF10/365 -> 3343.6847
B27: Cash & cash equivalents | C27: 900 | D27: 800 | E27: 1050 | F27: 900 | G27: 1500 | H27: =H17-H20-H21-H22-H26-H28-H29 -> 5187.1287 | I27: =I17-I20-I21-I22-I26-I28-I29 -> 9607.6809 | J27: =J17-J20-J21-J22-J26-J28-J29 -> 14784.334 | K27: =K17-K20-K21-K22-K26-K28-K29 -> 20741.456 | L27: =L17-L20-L21-L22-L26-L28-L29 -> 27460.638
B28: Trade receivables | C28: =C37*'Income Statement'!E7/365 -> 968.34795 | D28: =D37*'Income Statement'!H7/365 -> 1011.7589 | E28: =E37*'Income Statement'!K7/365 -> 1305.863 | F28: =F37*'Income Statement'!N7/365 -> 1291.1315 | G28: =G37*'Income Statement'!Q7/365 -> 2072.1096 | H28: =H37*'Income Statement'!T7/365 -> 2574.7944 | I28: =I37*'Income Statement'!W7/365 -> 3066.5004 | J28: =J37*'Income Statement'!Z7/365 -> 3542.7447 | K28: =K37*'Income Statement'!AC7/365 -> 4011.1934 | L28: =L37*'Income Statement'!AF7/365 -> 4489.2973
B29: Other assets (loans, advances, deferred tax, other financial) | C29: =C30-C26-C27-C28 -> 483.32603 | D29: =D30-D26-D27-D28 -> 1043.2137 | E29: =E30-E26-E27-E28 -> 680.35616 | F29: =F30-F26-F27-F28 -> 1242.0712 | G29: =G30-G26-G27-G28 -> 2300.5479 | H29: =G29/'Income Statement'!Q7*'Income Statement'!T7 -> 2858.6509 | I29: =H29/'Income Statement'!T7*'Income Statement'!W7 -> 3404.5647 | J29: =I29/'Income Statement'!W7*'Income Statement'!Z7 -> 3933.3123 | K29: =J29/'Income Statement'!Z7*'Income Statement'!AC7 -> 4453.4048 | L29: =K29/'Income Statement'!AC7*'Income Statement'!AF7 -> 4984.2169
B30: Total current & other assets | C30: 3455 | D30: 4085 | E30: 4369 | F30: 5147 | G30: 7449 | H30: =SUM(H26,H27,H28,H29) -> 12568.406 | I30: =SUM(I26,I27,I28,I29) -> 18385.521 | J30: =SUM(J26,J27,J28,J29) -> 24914.128 | K30: =SUM(K26,K27,K28,K29) -> 32202.165 | L30: =SUM(L26,L27,L28,L29) -> 40277.837
B32: TOTAL ASSETS | C32: =SUM(C20,C21,C22,C30) -> 11902 | D32: =SUM(D20,D21,D22,D30) -> 13993 | E32: =SUM(E20,E21,E22,E30) -> 16062 | F32: =SUM(F20,F21,F22,F30) -> 19951 | G32: =SUM(G20,G21,G22,G30) -> 25916 | H32: =SUM(H20,H21,H22,H30) -> 32660.111 | I32: =SUM(I20,I21,I22,I30) -> 40232.486 | J32: =SUM(J20,J21,J22,J30) -> 48572.515 | ... L32: =SUM(L20,L21,L22,L30) -> 67624.394
B33: Balance check (assets − equity & liabilities) | C33: =C32-C17 -> -2 | D33: =D32-D17 -> 1 | E33: =E32-E17 -> -2 | F33: =F32-F17 -> -1 | G33: =G32-G17 -> 0 | H33: =H32-H17 -> 0 | I33: =I32-I17 -> 0 | J33: =J32-J17 -> 0 | ... L33: =L32-L17 -> 0
B35: WORKING CAPITAL SCHEDULE
B36: Inventory days (on materials cost) | C36: 26 | D36: 23 | E36: 21 | F36: 24 | G36: 17 | H36: =G36 -> 17 | I36: =H36 -> 17 | J36: =I36 -> 17 | K36: =J36 -> 17 | L36: =K36 -> 17
B37: Trade receivable days (on sales) | C37: 17 | D37: 14 | E37: 15 | F37: 13 | G37: 16 | H37: =G37 -> 16 | I37: =H37 -> 16 | J37: =I37 -> 16 | K37: =J37 -> 16 | L37: =K37 -> 16
B38: Trade payable days (on materials cost) | C38: 93 | D38: 75 | E38: 80 | F38: 87 | G38: 90 | H38: =G38 -> 90 | I38: =H38 -> 90 | J38: =I38 -> 90 | K38: =J38 -> 90 | L38: =K38 -> 90
B39: Cash conversion cycle (days) | C39: =C36+C37-C38 -> -50 | D39: =D36+D37-D38 -> -38 | E39: =E36+E37-E38 -> -44 | F39: =F36+F37-F38 -> -50 | G39: =G36+G37-G38 -> -57 | H39: =H36+H37-H38 -> -57 | I39: =I36+I37-I38 -> -57 | J39: =J36+J37-J38 -> -57 | ... L39: =L36+L37-L38 -> -57
B40: Net working capital (inventory + receivables − payables) | C40: =C26+C28-C14 -> -1874.8384 | D40: =D26+D28-D14 -> -1769.1726 | E40: =E26+E28-E14 -> -2438.6164 | F40: =F26+F28-F14 -> -3207.5863 | G40: =G26+G28-G14 -> -4696.8904 | H40: =H26+H28-H14 -> -5789.4252 | I40: =I26+I28-I14 -> -6839.0624 | J40: =J26+J28-J14 -> -7852.7151 | ... L40: =L26+L28-L14 -> -9868.8783
B41: (Increase) / decrease in net working capital | D41: =C40-D40 -> -105.66575 | E41: =D40-E40 -> 669.44384 | F41: =E40-F40 -> 768.96986 | G41: =F40-G40 -> 1489.3041 | H41: =G40-H40 -> 1092.5348 | I41: =H40-I40 -> 1049.6372 | J41: =I40-J40 -> 1013.6526 | K41: =J40-K40 -> 1001.7437 | L41: =K40-L40 -> 1014.4196
B43: FIXED-ASSET, DEPRECIATION AND DEBT SCHEDULE
B44: Opening net block (PPE + CWIP) | D44: =C47 -> 3731 | E44: =D47 -> 4224 | F44: =E47 -> 4702 | G44: =F47 -> 5641 | H44: =G47 -> 6820 | I44: =H47 -> 8444.7049 | J44: =I47 -> 10199.965 | K44: =J47 -> 12011.387 | L44: =K47 -> 13822.173
B45: Add: capital expenditure | C45: 728 | D45: 997 | E45: 1055 | F45: 1780 | G45: 1925 | H45: ='Income Statement'!T7*'Guidance & Assumptions'!$C$34 -> 2466.9749 | I45: ='Income Statement'!W7*'Guidance & Assumptions'!$D$34 -> 2798.1816 | J45: ='Income Statement'!Z7*'Guidance & Assumptions'!$E$34 -> 3071.1168 | K45: ='Income Statement'!AC7*'Guidance & Assumptions'!$F$34 -> 3294.1926 | L45: ='Income Statement'!AF7*'Guidance & Assumptions'!$G$34 -> 3584.4233
B46: Less: depreciation & amortisation | C46: 611 | D46: 631 | E46: 700 | F46: 748 | G46: 901 | H46: =H44*H49 -> 842.27 | I46: =I44*I49 -> 1042.9211 | J46: =J44*J49 -> 1259.6957 | K46: =K44*K49 -> 1483.4062 | L46: =L44*L49 -> 1707.0383
B47: Closing net block (PPE + CWIP) | C47: =C20+C21 -> 3731 | D47: =D20+D21 -> 4224 | E47: =E20+E21 -> 4702 | F47: =F20+F21 -> 5641 | G47: =G20+G21 -> 6820 | H47: =H44+H45-H46 -> 8444.7049 | I47: =I44+I45-I46 -> 10199.965 | J47: =J44+J45-J46 -> 12011.387 | K47: =K44+K45-K46 -> 13822.173 | L47: =L44+L45-L46 -> 15699.558
B48: Capex as % of sales | C48: =C45/'Income Statement'!E7 -> 0.035015151 | D48: =D45/'Income Statement'!H7 -> 0.037796649 | E48: =E45/'Income Statement'!K7 -> 0.033201158 | F48: =F45/'Income Statement'!N7 -> 0.049102094 | G48: =G45/'Income Statement'!Q7 -> 0.040723503 | H48: =H45/'Income Statement'!T7 -> 0.042 | I48: =I45/'Income Statement'!W7 -> 0.04 | J48: =J45/'Income Statement'!Z7 -> 0.038 | K48: =K45/'Income Statement'!AC7 -> 0.036 | L48: =L45/'Income Statement'!AF7 -> 0.035
B49: D&A as % of opening net block | D49: =D46/D44 -> 0.16912356 | E49: =E46/E44 -> 0.1657197 | F49: =F46/F44 -> 0.15908124 | G49: =G46/G44 -> 0.15972345 | H49: 0.1235 | I49: 0.1235 | J49: 0.1235 | K49: 0.1235 | L49: 0.1235
...

Sheet Income Statement
B1: TVS MOTOR COMPANY LIMITED
B2: Fiscal year ending 31 March | C2: H1 | D2: H2 | E2: FY | F2: H1 | G2: H2 | H2: FY | I2: H1 | J2: H2 | K2: FY | L2: H1 | M2: H2 | N2: FY | O2: H1 | P2: H2 | Q2: FY | R2: H1 | S2: H2 | T2: FY | U2: H1 | V2: H2 | W2: FY | X2: H1 | Y2: H2 | Z2: FY | AA2: H1 | AB2: H2 | AC2: FY | AD2: H1 | AE2: H2 | AF2: FY
B3: All amounts in ₹ crores unless stated · Standalone (core automotive) — the entity carried into the FCFF model | C3: FY2022 | D3: FY2022 | E3: FY2022 | F3: FY2023 | G3: FY2023 | H3: FY2023 | I3: FY2024 | J3: FY2024 | K3: FY2024 | L3: FY2025 | M3: FY2025 | N3: FY2025 | O3: FY2026 | P3: FY2026 | Q3: FY2026 | R3: FY2027E | S3: FY2027E | T3: FY2027E | U3: FY2028E | V3: FY2028E | W3: FY2028E | X3: FY2029E | Y3: FY2029E | Z3: FY2029E | AA3: FY2030E | AB3: FY2030E | AC3: FY2030E | AD3: FY2031E | AE3: FY2031E | AF3: FY2031E
B5: INCOME STATEMENT
B7: Revenue from operations | C7: ='Revenue Segments'!C50 -> 9980 | D7: ='Revenue Segments'!D50 -> 10811 | E7: ='Revenue Segments'!E50 -> 20791 | F7: ='Revenue Segments'!F50 -> 12661 | G7: ='Revenue Segments'!G50 -> 13717 | H7: ='Revenue Segments'!H50 -> 26378 | I7: ='Revenue Segments'!I50 -> 15361 | J7: ='Revenue Segments'!J50 -> 16415 | ... AF7: ='Revenue Segments'!AF50 -> 102412.09
B8: Growth % (YoY) | F8: =(F7-C7)/C7 -> 0.26863727 | G8: =(G7-D7)/D7 -> 0.2688003 | H8: =(H7-E7)/E7 -> 0.26872204 | I8: =(I7-F7)/F7 -> 0.2132533 | J8: =(J7-G7)/G7 -> 0.19669024 | K8: =(K7-H7)/H7 -> 0.20464023 | L8: =(L7-I7)/I7 -> 0.14595404 | M8: =(M7-J7)/J7 -> 0.13603412 | ... AF8: =(AF7-AC7)/AC7 -> 0.11919242
B10: Cost of materials & components consumed (net of stock change) | C10: =E10*C7/E7 -> 7434.9584 | D10: =E10-C10 -> 8054.0416 | E10: 15489 | F10: =H10*F7/H7 -> 9369.2744 | G10: =H10-F10 -> 10150.726 | H10: 19520 | I10: =K10*I7/K7 -> 11198.312 | J10: =K10-I10 -> 11966.688 | K10: 23165 | L10: =N10*L7/N7 -> 12656.329 | M10: =N10-L10 -> 13407.671 | N10: 26064 | O10: =Q10*O7/Q7 -> 15741.111 | P10: =Q10-O10 -> 18103.889 | Q10: 33845 | R10: =R7*'Guidance & Assumptions'!$C$31 -> 19655.916 | S10: =S7*'Guidance & Assumptions'!$C$31 -> 22165.182 | T10: =T7*'Guidance & Assumptions'!$C$31 -> 41821.098 | U10: =U7*'Guidance & Assumptions'!$D$31 -> 23278.073 | V10: =V7*'Guidance & Assumptions'!$D$31 -> 26249.741 | W10: =W7*'Guidance & Assumptions'!$D$31 -> 49527.814 | X10: =X7*'Guidance & Assumptions'!$E$31 -> 26779.33 | Y10: =Y7*'Guidance & Assumptions'!$E$31 -> 30197.968 | Z10: =Z7*'Guidance & Assumptions'!$E$31 -> 56977.299 | AA10: =AA7*'Guidance & Assumptions'!$F$31 -> 30234.283 | AB10: =AB7*'Guidance & Assumptions'!$F$31 -> 34093.978 | AC10: =AC7*'Guidance & Assumptions'!$F$31 -> 64328.261 | AD10: =AD7*'Guidance & Assumptions'!$G$31 -> 33741.713 | AE10: =AE7*'Guidance & Assumptions'!$G$31 -> 38049.165 | AF10: =AF7*'Guidance & Assumptions'!$G$31 -> 71790.878
B11: as % of sales | C11: =C10/C7 -> 0.74498581 | D11: =D10/D7 -> 0.74498581 | E11: =E10/E7 -> 0.74498581 | F11: =F10/F7 -> 0.74001061 | G11: =G10/G7 -> 0.74001061 | H11: =H10/H7 -> 0.74001061 | I11: =I10/I7 -> 0.72900932 | J11: =J10/J7 -> 0.72900932 | ... AF11: =AF10/AF7 -> 0.701
B12: Employee benefits expense | C12: =E12*C7/E7 -> 578.89856 | D12: =E12-C12 -> 627.10144 | E12: 1206 | F12: =H12*F7/H7 -> 696.4558 | G12: =H12-F12 -> 754.5442 | H12: 1451 | I12: =K12*I7/K7 -> 845.00969 | J12: =K12-I12 -> 902.99031 | K12: 1748 | L12: =N12*L7/N7 -> 985.74081 | M12: =N12-L12 -> 1044.2592 | N12: 2030 | O12: =Q12*O7/Q7 -> 1187.3853 | P12: =Q12-O12 -> 1365.6147 | Q12: 2553 | R12: =R7*'Guidance & Assumptions'!$C$32 -> 1490.7577 | S12: =S7*'Guidance & Assumptions'!$C$32 -> 1681.0672 | T12: =T7*'Guidance & Assumptions'!$C$32 -> 3171.8249 | U12: =U7*'Guidance & Assumptions'!$D$32 -> 1775.4462 | V12: =V7*'Guidance & Assumptions'!$D$32 -> 2002.0989 | W12: =W7*'Guidance & Assumptions'!$D$32 -> 3777.5451 | X12: =X7*'Guidance & Assumptions'!$E$32 -> 2051.1828 | Y12: =Y7*'Guidance & Assumptions'!$E$32 -> 2313.0359 | Z12: =Z7*'Guidance & Assumptions'!$E$32 -> 4364.2186 | AA12: =AA7*'Guidance & Assumptions'!$F$32 -> 2322.4058 | AB12: =AB7*'Guidance & Assumptions'!$F$32 -> 2618.8831 | AC12: =AC7*'Guidance & Assumptions'!$F$32 -> 4941.2889 | AD12: =AD7*'Guidance & Assumptions'!$G$32 -> 2599.2189 | AE12: =AE7*'Guidance & Assumptions'!$G$32 -> 2931.0341 | AF12: =AF7*'Guidance & Assumptions'!$G$32 -> 5530.2531
B13: as % of sales | C13: =C12/C7 -> 0.058005868 | D13: =D12/D7 -> 0.058005868 | E13: =E12/E7 -> 0.058005868 | F13: =F12/F7 -> 0.055007961 | G13: =G12/G7 -> 0.055007961 | H13: =H12/H7 -> 0.055007961 | I13: =I12/I7 -> 0.05501007 | J13: =J12/J7 -> 0.05501007 | ... AF13: =AF12/AF7 -> 0.054
B14: Other expenses | C14: =E14*C7/E7 -> 1024.3528 | D14: =E14-C14 -> 1109.6472 | E14: 2134 | F14: =H14*F7/H7 -> 1311.3144 | G14: =H14-F14 -> 1420.6856 | H14: 2732 | I14: =K14*I7/K7 -> 1619.4408 | J14: =K14-I14 -> 1730.5592 | K14: 3350 | L14: =N14*L7/N7 -> 1793.7569 | M14: =N14-L14 -> 1900.2431 | N14: 3694 | O14: =Q14*O7/Q7 -> 2229.1962 | P14: =Q14-O14 -> 2563.8038 | Q14: 4793 | R14: =R7*'Guidance & Assumptions'!$C$33 -> 2760.6624 | S14: =S7*'Guidance & Assumptions'!$C$33 -> 3113.0874 | T14: =T7*'Guidance & Assumptions'!$C$33 -> 5873.7498 | U14: =U7*'Guidance & Assumptions'!$D$33 -> 3287.8633 | V14: =V7*'Guidance & Assumptions'!$D$33 -> 3707.5906 | W14: =W7*'Guidance & Assumptions'!$D$33 -> 6995.4539 | X14: =X7*'Guidance & Assumptions'!$E$33 -> 3798.4866 | Y14: =Y7*'Guidance & Assumptions'!$E$33 -> 4283.3998 | Z14: =Z7*'Guidance & Assumptions'!$E$33 -> 8081.8863 | AA14: =AA7*'Guidance & Assumptions'!$F$33 -> 4300.7514 | AB14: =AB7*'Guidance & Assumptions'!$F$33 -> 4849.7835 | AC14: =AC7*'Guidance & Assumptions'!$F$33 -> 9150.535 | AD14: =AD7*'Guidance & Assumptions'!$G$33 -> 4813.3684 | AE14: =AE7*'Guidance & Assumptions'!$G$33 -> 5427.841 | AF14: =AF7*'Guidance & Assumptions'!$G$33 -> 10241.209
B15: as % of sales | C15: =C14/C7 -> 0.10264057 | D15: =D14/D7 -> 0.10264057 | E15: =E14/E7 -> 0.10264057 | F15: =F14/F7 -> 0.10357116 | G15: =G14/G7 -> 0.10357116 | H15: =H14/H7 -> 0.10357116 | I15: =I14/I7 -> 0.10542548 | J15: =J14/J7 -> 0.10542548 | ... AF15: =AF14/AF7 -> 0.1
B16: Total operating expenditure | C16: =SUM(C10,C12,C14) -> 9038.2098 | D16: =SUM(D10,D12,D14) -> 9790.7902 | E16: =SUM(E10,E12,E14) -> 18829 | F16: =SUM(F10,F12,F14) -> 11377.045 | G16: =SUM(G10,G12,G14) -> 12325.955 | H16: =SUM(H10,H12,H14) -> 23703 | I16: =SUM(I10,I12,I14) -> 13662.763 | J16: =SUM(J10,J12,J14) -> 14600.237 | ... AF16: =SUM(AF10,AF12,AF14) -> 87562.34
B18: EBITDA | C18: =C7-C16 -> 941.7902 | D18: =D7-D16 -> 1020.2098 | E18: =E7-E16 -> 1962 | F18: =F7-F16 -> 1283.9554 | G18: =G7-G16 -> 1391.0446 | H18: =H7-H16 -> 2675 | I18: =I7-I16 -> 1698.2374 | J18: =J7-J16 -> 1814.7626 | ... AF18: =AF7-AF16 -> 14849.754
B19: EBITDA margin | C19: =C18/C7 -> 0.094367755 | D19: =D18/D7 -> 0.094367755 | E19: =E18/E7 -> 0.094367755 | F19: =F18/F7 -> 0.10141027 | G19: =G18/G7 -> 0.10141027 | H19: =H18/H7 -> 0.10141027 | I19: =I18/I7 -> 0.11055514 | J19: =J18/J7 -> 0.11055514 | ... AF19: =AF18/AF7 -> 0.145
B21: Depreciation & amortisation | C21: =E21/2 -> 305.5 | D21: =E21-C21 -> 305.5 | E21: 611 | F21: =H21/2 -> 315.5 | G21: =H21-F21 -> 315.5 | H21: 631 | I21: =K21/2 -> 350 | J21: =K21-I21 -> 350 | K21: 700 | L21: =N21/2 -> 374 | M21: =N21-L21 -> 374 | N21: 748 | O21: =Q21/2 -> 450.5 | P21: =Q21-O21 -> 450.5 | Q21: 901 | R21: =T21/2 -> 421.135 | S21: =T21/2 -> 421.135 | T21: ='Balance Sheet'!H46 -> 842.27 | U21: =W21/2 -> 521.46053 | V21: =W21/2 -> 521.46053 | W21: ='Balance Sheet'!I46 -> 1042.9211 | X21: =Z21/2 -> 629.84786 | Y21: =Z21/2 -> 629.84786 | Z21: ='Balance Sheet'!J46 -> 1259.6957 | AA21: =AC21/2 -> 741.70312 | AB21: =AC21/2 -> 741.70312 | AC21: ='Balance Sheet'!K46 -> 1483.4062 | AD21: =AF21/2 -> 853.51917 | AE21: =AF21/2 -> 853.51917 | AF21: ='Balance Sheet'!L46 -> 1707.0383
B22: EBIT / operating income | C22: =C18-C21 -> 636.2902 | D22: =D18-D21 -> 714.7098 | E22: =E18-E21 -> 1351 | F22: =F18-F21 -> 968.45538 | G22: =G18-G21 -> 1075.5446 | H22: =H18-H21 -> 2044 | I22: =I18-I21 -> 1348.2374 | J22: =J18-J21 -> 1464.7626 | ... AF22: =AF18-AF21 -> 13142.715
B23: EBIT margin | C23: =C22/C7 -> 0.063756533 | D23: =D22/D7 -> 0.0661095 | E23: =E22/E7 -> 0.064980039 | F23: =F22/F7 -> 0.076491223 | G23: =G22/G7 -> 0.07840961 | H23: =H22/H7 -> 0.077488816 | I23: =I22/I7 -> 0.087770161 | J23: =J22/J7 -> 0.089233174 | ... AF23: =AF22/AF7 -> 0.12833167
B25: Other income, net | C25: =E25/2 -> -5.5 | D25: =E25-C25 -> -5.5 | E25: -11 | F25: =H25/2 -> 50.5 | G25: =H25-F25 -> 50.5 | H25: 101 | I25: =K25/2 -> 74.5 | J25: =K25-I25 -> 74.5 | K25: 149 | L25: =N25/2 -> -12 | M25: =N25-L25 -> -12 | N25: -24 | O25: =Q25/2 -> -35.5 | P25: =Q25-O25 -> -35.5 | Q25: -71 | R25: =T25/2 -> 0 | S25: =T25-R25 -> 0 | T25: ='Guidance & Assumptions'!$C$38 -> 0 | U25: =W25/2 -> 0 | V25: =W25-U25 -> 0 | W25: ='Guidance & Assumptions'!$D$38 -> 0 | X25: =Z25/2 -> 0 | Y25: =Z25-X25 -> 0 | Z25: ='Guidance & Assumptions'!$E$38 -> 0 | AA25: =AC25/2 -> 0 | AB25: =AC25-AA25 -> 0 | AC25: ='Guidance & Assumptions'!$F$38 -> 0 | AD25: =AF25/2 -> 0 | AE25: =AF25-AD25 -> 0 | AF25: ='Guidance & Assumptions'!$G$38 -> 0
B26: Finance cost | C26: =E26/2 -> 63 | D26: =E26-C26 -> 63 | E26: 126 | F26: =H26/2 -> 70.5 | G26: =H26-F26 -> 70.5 | H26: 141 | I26: =K26/2 -> 91 | J26: =K26-I26 -> 91 | K26: 182 | L26: =N26/2 -> 69.5 | M26: =N26-L26 -> 69.5 | N26: 139 | O26: =Q26/2 -> 102 | P26: =Q26-O26 -> 102 | Q26: 204 | R26: =T26/2 -> 135.8812 | S26: =T26-R26 -> 135.8812 | T26: ='Balance Sheet'!H56 -> 271.7624 | U26: =W26/2 -> 135.8812 | V26: =W26-U26 -> 135.8812 | W26: ='Balance Sheet'!I56 -> 271.7624 | X26: =Z26/2 -> 135.8812 | Y26: =Z26-X26 -> 135.8812 | Z26: ='Balance Sheet'!J56 -> 271.7624 | AA26: =AC26/2 -> 135.8812 | AB26: =AC26-AA26 -> 135.8812 | AC26: ='Balance Sheet'!K56 -> 271.7624 | AD26: =AF26/2 -> 135.8812 | AE26: =AF26-AD26 -> 135.8812 | AF26: ='Balance Sheet'!L56 -> 271.7624
B28: Profit before tax | C28: =C22+C25-C26 -> 567.7902 | D28: =D22+D25-D26 -> 646.2098 | E28: =E22+E25-E26 -> 1214 | F28: =F22+F25-F26 -> 948.45538 | G28: =G22+G25-G26 -> 1055.5446 | H28: =H22+H25-H26 -> 2004 | I28: =I22+I25-I26 -> 1331.7374 | J28: =J22+J25-J26 -> 1448.2626 | ... AF28: =AF22+AF25-AF26 -> 12870.953
B29: PBT margin | C29: =C28/C7 -> 0.056892805 | D29: =D28/D7 -> 0.059773361 | E29: =E28/E7 -> 0.05839065 | F29: =F28/F7 -> 0.074911569 | G29: =G28/G7 -> 0.076951565 | H29: =H28/H7 -> 0.075972401 | I29: =I28/I7 -> 0.086696012 | J29: =J28/J7 -> 0.088227996 | ... AF29: =AF28/AF7 -> 0.12567806
B30: Reported PBT (audited) | E30: 1213 | H30: 2003 | K30: 2781 | N30: 3551 | Q30: 4904
B31: Difference (rounding) | E31: =E28-E30 -> 1 | H31: =H28-H30 -> 1 | K31: =K28-K30 -> -1 | N31: =N28-N30 -> 1 | Q31: =Q28-Q30 -> -1
B33: Tax expense | C33: =E33/2 -> 159.5 | D33: =E33-C33 -> 159.5 | E33: 319 | F33: =H33/2 -> 256 | G33: =H33-F33 -> 256 | H33: 512 | I33: =K33/2 -> 349 | J33: =K33-I33 -> 349 | K33: 698 | L33: =N33/2 -> 458.5 | M33: =N33-L33 -> 458.5 | N33: 917 | O33: =Q33/2 -> 644.5 | P33: =Q33-O33 -> 644.5 | Q33: 1289 | R33: =R28*'Guidance & Assumptions'!$C$35 -> 790.90971 | S33: =S28*'Guidance & Assumptions'!$C$35 -> 909.77491 | T33: =T28*'Guidance & Assumptions'!$C$35 -> 1700.6846 | U33: =U28*'Guidance & Assumptions'!$D$35 -> 976.57327 | V33: =V28*'Guidance & Assumptions'!$D$35 -> 1122.3638 | W33: =W28*'Guidance & Assumptions'!$D$35 -> 2098.9371 | X33: =X28*'Guidance & Assumptions'!$E$35 -> 1155.3375 | Y33: =Y28*'Guidance & Assumptions'!$E$35 -> 1327.4317 | Z33: =Z28*'Guidance & Assumptions'!$E$35 -> 2482.7692 | AA33: =AA28*'Guidance & Assumptions'!$F$35 -> 1327.0858 | AB33: =AB28*'Guidance & Assumptions'!$F$35 -> 1524.6995 | AC33: =AC28*'Guidance & Assumptions'!$F$35 -> 2851.7853 | AD33: =AD28*'Guidance & Assumptions'!$G$35 -> 1507.6789 | AE33: =AE28*'Guidance & Assumptions'!$G$35 -> 1731.9399 | AF33: =AF28*'Guidance & Assumptions'!$G$35 -> 3239.6188
B34: Effective tax rate | C34: =C33/C28 -> 0.28091362 | D34: =D33/D28 -> 0.24682386 | E34: =E33/E28 -> 0.26276771 | F34: =F33/F28 -> 0.26991254 | G34: =G33/G28 -> 0.24252883 | H34: =H33/H28 -> 0.25548902 | I34: =I33/I28 -> 0.26206367 | J34: =J33/J28 -> 0.2409784 | ... AF34: =AF33/AF28 -> 0.2517
B36: PROFIT AFTER TAX | C36: =C28-C33 -> 408.2902 | D36: =D28-D33 -> 486.7098 | E36: =E28-E33 -> 895 | F36: =F28-F33 -> 692.45538 | G36: =G28-G33 -> 799.54462 | H36: =H28-H33 -> 1492 | I36: =I28-I33 -> 982.73744 | J36: =J28-J33 -> 1099.2626 | ... AF36: =AF28-AF33 -> 9631.3341
B37: PAT margin | C37: =C36/C7 -> 0.040910841 | D37: =D36/D7 -> 0.045019869 | E37: =E36/E7 -> 0.043047472 | F37: =F36/F7 -> 0.054691997 | G37: =G36/G7 -> 0.058288592 | H37: =H36/H7 -> 0.056562287 | I37: =I36/I7 -> 0.063976137 | J37: =J36/J7 -> 0.066966954 | ... AF37: =AF36/AF7 -> 0.094044889
B38: Reported PAT (audited) | E38: 894 | H38: 1491 | K38: 2083 | N38: 2634 | Q38: 3615
B39: Difference (rounding) | E39: =E36-E38 -> 1 | H39: =H36-H38 -> 1 | K39: =K36-K38 -> -1 | N39: =N36-N38 -> 1 | Q39: =Q36-Q38 -> -1
B41: Weighted average shares outstanding (crore) | C41: 47.5087 | D41: 47.5087 | E41: 47.5087 | F41: 47.5087 | G41: 47.5087 | H41: 47.5087 | I41: 47.5087 | J41: 47.5087 | K41: 47.5087 | L41: 47.5087 | M41: 47.5087 | N41: 47.5087 | O41: 47.5087 | P41: 47.5087 | Q41: 47.5087 | R41: 47.5087 | S41: 47.5087 | T41: 47.5087 | U41: 47.5087 | V41: 47.5087 | W41: 47.5087 | X41: 47.5087 | Y41: 47.5087 | Z41: 47.5087 | AA41: 47.5087 | AB41: 47.5087 | AC41: 47.5087 | AD41: 47.5087 | AE41: 47.5087 | AF41: 47.5087
B42: Earnings per share (₹) | C42: =C36/C41 -> 8.594009 | D42: =D36/D41 -> 10.244646 | E42: =E36/E41 -> 18.838655 | F42: =F36/F41 -> 14.575338 | G42: =G36/G41 -> 16.829436 | H42: =H36/H41 -> 31.404774 | I42: =I36/I41 -> 20.685421 | J42: =J36/J41 -> 23.138132 | ... AF42: =AF36/AF41 -> 202.7278
B43: Dividend per share (₹) | E43: =E44*E42 -> 3.767731 | H43: =H44*H42 -> 5.0247639 | K43: =K44*K42 -> 7.8882394 | N43: =N44*N42 -> 9.9834346 | Q43: =Q44*Q42 -> 12.171244 | T43: =T44*T42 -> 19.156478 | W43: =W44*W42 -> 24.955853 | Z43: =Z44*Z42 -> 31.073182 | AC43: =AC44*AC42 -> 37.476196 | AF43: =AF44*AF42 -> 44.600115
B44: Dividend payout ratio | E44: 0.2 | H44: 0.16 | K44: 0.18 | N44: 0.18 | Q44: 0.16 | T44: ='Guidance & Assumptions'!C39 -> 0.18 | W44: ='Guidance & Assumptions'!D39 -> 0.19 | Z44: ='Guidance & Assumptions'!E39 -> 0.2 | AC44: ='Guidance & Assumptions'!F39 -> 0.21 | AF44: ='Guidance & Assumptions'!G39 -> 0.22
B45: Dividend paid (₹ cr) | E45: =E43*E41 -> 179 | H45: =H43*H41 -> 238.72 | K45: =K43*K41 -> 374.76 | N45: =N43*N41 -> 474.3 | Q45: =Q43*Q41 -> 578.24 | T45: =T43*T41 -> 910.09938 | W45: =W43*W41 -> 1185.6201 | Z45: =Z43*Z41 -> 1476.2465 | AC45: =AC43*AC41 -> 1780.4453 | AF45: =AF43*AF41 -> 2118.8935
B47: Market price per share (₹) | E47: 662 | H47: 1061 | K47: 2051 | N47: 2375 | Q47: 3870
B48: Market capitalisation (₹ cr) | E48: =E47*E41 -> 31450.759 | H48: =H47*H41 -> 50406.731 | K48: =K47*K41 -> 97440.344 | N48: =N47*N41 -> 112833.16 | Q48: =Q47*Q41 -> 183858.67
B50: RATIO ANALYSIS (full-year columns)
B51: Contribution margin proxy (1 − RM % of sales) | E51: =1-E11 -> 0.25501419 | H51: =1-H11 -> 0.25998939 | K51: =1-K11 -> 0.27099068 | N51: =1-N11 -> 0.28101294 | Q51: =1-Q11 -> 0.28400677 | T51: =1-T11 -> 0.288 | W51: =1-W11 -> 0.292 | Z51: =1-Z11 -> 0.295 | AC51: =1-AC11 -> 0.297 | AF51: =1-AF11 -> 0.299
B52: EBITDA margin | E52: =E19 -> 0.094367755 | H52: =H19 -> 0.10141027 | K52: =K19 -> 0.11055514 | N52: =N19 -> 0.12311385 | Q52: =Q19 -> 0.12860165 | T52: =T19 -> 0.134 | W52: =W19 -> 0.138 | Z52: =Z19 -> 0.141 | AC52: =AC19 -> 0.143 | AF52: =AF19 -> 0.145
...

Sheet Cash Flows
B1: TVS MOTOR COMPANY LIMITED
B2: Fiscal year ending 31 March | C2: Actual | D2: Actual | E2: Actual | F2: Actual | G2: Actual | H2: Estimate | I2: Estimate | J2: Estimate | K2: Estimate | L2: Estimate
B3: All amounts in ₹ crores unless stated · Standalone (core automotive) — indirect method | C3: FY2022 | D3: FY2023 | E3: FY2024 | F3: FY2025 | G3: FY2026 | H3: FY2027E | I3: FY2028E | J3: FY2029E | K3: FY2030E | L3: FY2031E
B5: CASH FLOW STATEMENT
B7: Profit before tax | C7: ='Income Statement'!E28 -> 1214 | D7: ='Income Statement'!H28 -> 2004 | E7: ='Income Statement'!K28 -> 2780 | F7: ='Income Statement'!N28 -> 3552 | G7: ='Income Statement'!Q28 -> 4903 | H7: ='Income Statement'!T28 -> 6756.7923 | I7: ='Income Statement'!W28 -> 8339.043 | J7: ='Income Statement'!Z28 -> 9864.0016 | K7: ='Income Statement'!AC28 -> 11330.096 | L7: ='Income Statement'!AF28 -> 12870.953
B8: Add: depreciation & amortisation | C8: ='Income Statement'!E21 -> 611 | D8: ='Income Statement'!H21 -> 631 | E8: ='Income Statement'!K21 -> 700 | F8: ='Income Statement'!N21 -> 748 | G8: ='Income Statement'!Q21 -> 901 | H8: ='Income Statement'!T21 -> 842.27 | I8: ='Income Statement'!W21 -> 1042.9211 | J8: ='Income Statement'!Z21 -> 1259.6957 | K8: ='Income Statement'!AC21 -> 1483.4062 | L8: ='Income Statement'!AF21 -> 1707.0383
B9: Add: finance cost | C9: ='Income Statement'!E26 -> 126 | D9: ='Income Statement'!H26 -> 141 | E9: ='Income Statement'!K26 -> 182 | F9: ='Income Statement'!N26 -> 139 | G9: ='Income Statement'!Q26 -> 204 | H9: ='Income Statement'!T26 -> 271.7624 | I9: ='Income Statement'!W26 -> 271.7624 | J9: ='Income Statement'!Z26 -> 271.7624 | K9: ='Income Statement'!AC26 -> 271.7624 | L9: ='Income Statement'!AF26 -> 271.7624
B10: Less: other income | C10: =-'Income Statement'!E25 -> 11 | D10: =-'Income Statement'!H25 -> -101 | E10: =-'Income Statement'!K25 -> -149 | F10: =-'Income Statement'!N25 -> 24 | G10: =-'Income Statement'!Q25 -> 71 | H10: =-'Income Statement'!T25 -> 0 | I10: =-'Income Statement'!W25 -> 0 | J10: =-'Income Statement'!Z25 -> 0 | K10: =-'Income Statement'!AC25 -> 0 | L10: =-'Income Statement'!AF25 -> 0
B11: Operating profit before working capital changes | C11: =SUM(C7:C10) -> 1962 | D11: =SUM(D7:D10) -> 2675 | E11: =SUM(E7:E10) -> 3513 | F11: =SUM(F7:F10) -> 4463 | G11: =SUM(G7:G10) -> 6079 | H11: =SUM(H7:H10) -> 7870.8247 | I11: =SUM(I7:I10) -> 9653.7264 | J11: =SUM(J7:J10) -> 11395.46 | ... L11: =SUM(L7:L10) -> 14849.754
B12: Changes in working capital | C12: 0 | D12: ='Balance Sheet'!D41 -> -105.66575 | E12: ='Balance Sheet'!E41 -> 669.44384 | F12: ='Balance Sheet'!F41 -> 768.96986 | G12: ='Balance Sheet'!G41 -> 1489.3041 | H12: ='Balance Sheet'!H41 -> 1092.5348 | I12: ='Balance Sheet'!I41 -> 1049.6372 | J12: ='Balance Sheet'!J41 -> 1013.6526 | K12: ='Balance Sheet'!K41 -> 1001.7437 | L12: ='Balance Sheet'!L41 -> 1014.4196
B13: Cash generated from operations | C13: =C11+C12 -> 1962 | D13: =D11+D12 -> 2569.3342 | E13: =E11+E12 -> 4182.4438 | F13: =F11+F12 -> 5231.9699 | G13: =G11+G12 -> 7568.3041 | H13: =H11+H12 -> 8963.3595 | I13: =I11+I12 -> 10703.364 | J13: =J11+J12 -> 12409.112 | ... L13: =L11+L12 -> 15864.173
B14: Less: taxes paid | C14: =-'Income Statement'!E33 -> -319 | D14: =-'Income Statement'!H33 -> -512 | E14: =-'Income Statement'!K33 -> -698 | F14: =-'Income Statement'!N33 -> -917 | G14: =-'Income Statement'!Q33 -> -1289 | H14: =-'Income Statement'!T33 -> -1700.6846 | I14: =-'Income Statement'!W33 -> -2098.9371 | J14: =-'Income Statement'!Z33 -> -2482.7692 | K14: =-'Income Statement'!AC33 -> -2851.7853 | L14: =-'Income Statement'!AF33 -> -3239.6188
B15: NET CASH FROM OPERATING ACTIVITIES | C15: =C13+C14 -> 1643 | D15: =D13+D14 -> 2057.3342 | E15: =E13+E14 -> 3484.4438 | F15: =F13+F14 -> 4314.9699 | G15: =G13+G14 -> 6279.3041 | H15: =H13+H14 -> 7262.6749 | I15: =I13+I14 -> 8604.4265 | J15: =J13+J14 -> 9926.3432 | ... L15: =L13+L14 -> 12624.554
B16: Reported CFO (audited) | C16: 1498 | D16: 1993 | E16: 3617 | F16: 4292 | G16: 5730
B17: Difference — other non-cash items & timing | C17: =C16-C15 -> -145 | D17: =D16-D15 -> -64.334247 | E17: =E16-E15 -> 132.55616 | F17: =F16-F15 -> -22.969863 | G17: =G16-G15 -> -549.30411
B19: INVESTING ACTIVITIES
B20: Capital expenditure | C20: =-'Balance Sheet'!C45 -> -728 | D20: =-'Balance Sheet'!D45 -> -997 | E20: =-'Balance Sheet'!E45 -> -1055 | F20: =-'Balance Sheet'!F45 -> -1780 | G20: =-'Balance Sheet'!G45 -> -1925 | H20: =-'Balance Sheet'!H45 -> -2466.9749 | I20: =-'Balance Sheet'!I45 -> -2798.1816 | J20: =-'Balance Sheet'!J45 -> -3071.1168 | ... L20: =-'Balance Sheet'!L45 -> -3584.4233
B21: Investment in subsidiaries & other investments | C21: 0 | D21: =-('Balance Sheet'!D22-'Balance Sheet'!C22) -> -968 | E21: =-('Balance Sheet'!E22-'Balance Sheet'!D22) -> -1307 | F21: =-('Balance Sheet'!F22-'Balance Sheet'!E22) -> -2172 | G21: =-('Balance Sheet'!G22-'Balance Sheet'!F22) -> -2484 | H21: =-('Balance Sheet'!H22-'Balance Sheet'!G22) -> 0 | I21: =-('Balance Sheet'!I22-'Balance Sheet'!H22) -> 0 | J21: =-('Balance Sheet'!J22-'Balance Sheet'!I22) -> 0 | K21: =-('Balance Sheet'!K22-'Balance Sheet'!J22) -> 0 | L21: =-('Balance Sheet'!L22-'Balance Sheet'!K22) -> 0
B22: NET CASH FROM INVESTING ACTIVITIES | C22: =SUM(C20:C21) -> -728 | D22: =SUM(D20:D21) -> -1965 | E22: =SUM(E20:E21) -> -2362 | F22: =SUM(F20:F21) -> -3952 | G22: =SUM(G20:G21) -> -4409 | H22: =SUM(H20:H21) -> -2466.9749 | I22: =SUM(I20:I21) -> -2798.1816 | J22: =SUM(J20:J21) -> -3071.1168 | ... L22: =SUM(L20:L21) -> -3584.4233
B23: Reported CFI (audited) | C23: -2141 | D23: -2312 | E23: -1896 | F23: -3870 | G23: -4310
B25: FINANCING ACTIVITIES
B26: Net borrowing / (repayment) | C26: 0 | D26: ='Balance Sheet'!D52 -> 700 | E26: ='Balance Sheet'!E52 -> -699 | F26: ='Balance Sheet'!F52 -> 73 | G26: ='Balance Sheet'!G52 -> 1696 | H26: ='Balance Sheet'!H52 -> 0 | I26: ='Balance Sheet'!I52 -> 0 | J26: ='Balance Sheet'!J52 -> 0 | K26: ='Balance Sheet'!K52 -> 0 | L26: ='Balance Sheet'!L52 -> 0
B27: Dividend paid | C27: =-'Income Statement'!E45 -> -179 | D27: =-'Income Statement'!H45 -> -238.72 | E27: =-'Income Statement'!K45 -> -374.76 | F27: =-'Income Statement'!N45 -> -474.3 | G27: =-'Income Statement'!Q45 -> -578.24 | H27: =-'Income Statement'!T45 -> -910.09938 | I27: =-'Income Statement'!W45 -> -1185.6201 | J27: =-'Income Statement'!Z45 -> -1476.2465 | K27: =-'Income Statement'!AC45 -> -1780.4453 | L27: =-'Income Statement'!AF45 -> -2118.8935
B28: Finance cost paid | C28: =-'Income Statement'!E26 -> -126 | D28: =-'Income Statement'!H26 -> -141 | E28: =-'Income Statement'!K26 -> -182 | F28: =-'Income Statement'!N26 -> -139 | G28: =-'Income Statement'!Q26 -> -204 | H28: =-'Income Statement'!T26 -> -271.7624 | I28: =-'Income Statement'!W26 -> -271.7624 | J28: =-'Income Statement'!Z26 -> -271.7624 | K28: =-'Income Statement'!AC26 -> -271.7624 | L28: =-'Income Statement'!AF26 -> -271.7624
B29: NET CASH FROM FINANCING ACTIVITIES | C29: =SUM(C26:C28) -> -305 | D29: =SUM(D26:D28) -> 320.28 | E29: =SUM(E26:E28) -> -1255.76 | F29: =SUM(F26:F28) -> -540.3 | G29: =SUM(G26:G28) -> 913.76 | H29: =SUM(H26:H28) -> -1181.8618 | I29: =SUM(I26:I28) -> -1457.3825 | J29: =SUM(J26:J28) -> -1748.0089 | ... L29: =SUM(L26:L28) -> -2390.6559
B30: Reported CFF (audited) | C30: 113 | D30: 225 | E30: -1470 | F30: -588 | G30: -1344
B32: NET INCREASE / (DECREASE) IN CASH | C32: =C15+C22+C29 -> 610 | D32: =D15+D22+D29 -> 412.61425 | E32: =E15+E22+E29 -> -133.31616 | F32: =F15+F22+F29 -> -177.33014 | G32: =G15+G22+G29 -> 2784.0641 | H32: =H15+H22+H29 -> 3613.8382 | I32: =I15+I22+I29 -> 4348.8624 | J32: =J15+J22+J29 -> 5107.2175 | ... L32: =L15+L22+L29 -> 6649.4752
B33: Opening cash & cash equivalents | D33: ='Balance Sheet'!C27 -> 900 | E33: ='Balance Sheet'!D27 -> 800 | F33: ='Balance Sheet'!E27 -> 1050 | G33: ='Balance Sheet'!F27 -> 900 | H33: ='Balance Sheet'!G27 -> 1500 | I33: ='Balance Sheet'!H27 -> 5187.1287 | J33: ='Balance Sheet'!I27 -> 9607.6809 | K33: ='Balance Sheet'!J27 -> 14784.334 | L33: ='Balance Sheet'!K27 -> 20741.456
B34: Closing cash & cash equivalents | C34: ='Balance Sheet'!C27 -> 900 | D34: ='Balance Sheet'!D27 -> 800 | E34: ='Balance Sheet'!E27 -> 1050 | F34: ='Balance Sheet'!F27 -> 900 | G34: ='Balance Sheet'!G27 -> 1500 | H34: ='Balance Sheet'!H27 -> 5187.1287 | I34: ='Balance Sheet'!I27 -> 9607.6809 | J34: ='Balance Sheet'!J27 -> 14784.334 | ... L34: ='Balance Sheet'!L27 -> 27460.638
B36: FREE CASH FLOW ANALYSIS
B37: Free cash flow to firm = EBIT×(1−t) + D&A − capex − ΔNWC | C37: ='Income Statement'!E22*(1-'Income Statement'!E34)+'Income Statement'!E21-'Balance Sheet'!C45+'Balance Sheet'!C41 -> 879.00082 | D37: ='Income Statement'!H22*(1-'Income Statement'!H34)+'Income Statement'!H21-'Balance Sheet'!D45+'Balance Sheet'!D41 -> 1050.1147 | E37: ='Income Statement'!K22*(1-'Income Statement'!K34)+'Income Statement'!K21-'Balance Sheet'!E45+'Balance Sheet'!E41 -> 2421.1582 | F37: ='Income Statement'!N22*(1-'Income Statement'!N34)+'Income Statement'!N21-'Balance Sheet'!F45+'Balance Sheet'!F41 -> 2492.8891 | G37: ='Income Statement'!Q22*(1-'Income Statement'!Q34)+'Income Statement'!Q21-'Balance Sheet'!G45+'Balance Sheet'!G41 -> 4282.0065 | H37: ='Income Statement'!T22*(1-'Income Statement'!T34)+'Income Statement'!T21-'Balance Sheet'!H45+'Balance Sheet'!H41 -> 4727.2974 | I37: ='Income Statement'!W22*(1-'Income Statement'!W34)+'Income Statement'!W21-'Balance Sheet'!I45+'Balance Sheet'!I41 -> 5737.8423 | J37: ='Income Statement'!Z22*(1-'Income Statement'!Z34)+'Income Statement'!Z21-'Balance Sheet'!J45+'Balance Sheet'!J41 -> 6786.8238 | K37: ='Income Statement'!AC22*(1-'Income Statement'!AC34)+'Income Statement'!AC21-'Balance Sheet'!K45+'Balance Sheet'!K41 -> 7872.6283 | L37: ='Income Statement'!AF22*(1-'Income Statement'!AF34)+'Income Statement'!AF21-'Balance Sheet'!L45+'Balance Sheet'!L41 -> 8971.7285
B38: Free cash flow to equity = FCFF − interest×(1−t) + net borrowing | C38: =C37-'Income Statement'!E26*(1-'Income Statement'!E34)+'Balance Sheet'!C52 -> 786.10956 | D38: =D37-'Income Statement'!H26*(1-'Income Statement'!H34)+'Balance Sheet'!D52 -> 1645.1386 | E38: =E37-'Income Statement'!K26*(1-'Income Statement'!K34)+'Balance Sheet'!E52 -> 1585.8546 | F38: =F37-'Income Statement'!N26*(1-'Income Statement'!N34)+'Balance Sheet'!F52 -> 2462.7739 | G38: =G37-'Income Statement'!Q26*(1-'Income Statement'!Q34)+'Balance Sheet'!G52 -> 5827.6382 | H38: =H37-'Income Statement'!T26*(1-'Income Statement'!T34)+'Balance Sheet'!H52 -> 4523.9376 | I38: =I37-'Income Statement'!W26*(1-'Income Statement'!W34)+'Balance Sheet'!I52 -> 5534.4825 | J38: =J37-'Income Statement'!Z26*(1-'Income Statement'!Z34)+'Balance Sheet'!J52 -> 6583.464 | K38: =K37-'Income Statement'!AC26*(1-'Income Statement'!AC34)+'Balance Sheet'!K52 -> 7669.2685 | L38: =L37-'Income Statement'!AF26*(1-'Income Statement'!AF34)+'Balance Sheet'!L52 -> 8768.3687
B39: FCFF conversion (FCFF / EBITDA) | C39: =C37/'Income Statement'!E18 -> 0.44801265 | D39: =D37/'Income Statement'!H18 -> 0.39256624 | E39: =E37/'Income Statement'!K18 -> 0.68919961 | F39: =F37/'Income Statement'!N18 -> 0.55856802 | G39: =G37/'Income Statement'!Q18 -> 0.70439325 | H39: =H37/'Income Statement'!T18 -> 0.60061018 | I39: =I37/'Income Statement'!W18 -> 0.59436554 | J39: =J37/'Income Statement'!Z18 -> 0.59557262 | K39: =K37/'Income Statement'!AC18 -> 0.60164072 | L39: =L37/'Income Statement'!AF18 -> 0.60416682
B40: Cash conversion (CFO / EBITDA) | C40: =C15/'Income Statement'!E18 -> 0.83741081 | D40: =D15/'Income Statement'!H18 -> 0.76909691 | E40: =E15/'Income Statement'!K18 -> 0.99187129 | F40: =F15/'Income Statement'!N18 -> 0.9668317 | G40: =G15/'Income Statement'!Q18 -> 1.0329502 | H40: =H15/'Income Statement'!T18 -> 0.92273366 | I40: =I15/'Income Statement'!W18 -> 0.89130623 | J40: =J15/'Income Statement'!Z18 -> 0.87107878 | K40: =K15/'Income Statement'!AC18 -> 0.85861643 | L40: =L15/'Income Statement'!AF18 -> 0.85015244

Sheet Graphical Representation
B1: TVS MOTOR COMPANY LIMITED
B2: Fiscal year ending 31 March
B3: All charts are live links to the model tabs — change a driver or a Control Panel switch and every exhibit below re-draws. Source data sits from row 200.
B5: GROWTH AND MIX
B47: CAPITAL DEPLOYMENT AND COST
B89: RETURNS, WORKING CAPITAL AND BALANCE SHEET
B131: VALUATION
B173: RISK AND EARNINGS QUALITY
B199: CHART SOURCE DATA — linked to the model, do not overwrite
B201: Year | C201: FY2022 | D201: FY2023 | E201: FY2024 | F201: FY2025 | G201: FY2026 | H201: FY2027E | I201: FY2028E | J201: FY2029E | K201: FY2030E | L201: FY2031E
B202: Motorcycles | C202: ='Revenue Segments'!AH81 -> 0 | D202: ='Revenue Segments'!AI81 -> 0 | E202: ='Revenue Segments'!AJ81 -> 0 | F202: ='Revenue Segments'!AK81 -> 0 | G202: ='Revenue Segments'!AL81 -> 0 | H202: ='Revenue Segments'!AM81 -> 0 | I202: ='Revenue Segments'!AN81 -> 0 | J202: ='Revenue Segments'!AO81 -> 0 | ... L202: ='Revenue Segments'!AQ81 -> 0
B203: Scooters — ICE | C203: ='Revenue Segments'!AH82 -> 0 | D203: ='Revenue Segments'!AI82 -> 0 | E203: ='Revenue Segments'!AJ82 -> 0 | F203: ='Revenue Segments'!AK82 -> 0 | G203: ='Revenue Segments'!AL82 -> 0 | H203: ='Revenue Segments'!AM82 -> 0 | I203: ='Revenue Segments'!AN82 -> 0 | J203: ='Revenue Segments'!AO82 -> 0 | ... L203: ='Revenue Segments'!AQ82 -> 0
B204: Electric 2W | C204: ='Revenue Segments'!AH83 -> 0 | D204: ='Revenue Segments'!AI83 -> 0 | E204: ='Revenue Segments'!AJ83 -> 0 | F204: ='Revenue Segments'!AK83 -> 0 | G204: ='Revenue Segments'!AL83 -> 0 | H204: ='Revenue Segments'!AM83 -> 0 | I204: ='Revenue Segments'!AN83 -> 0 | J204: ='Revenue Segments'!AO83 -> 0 | ... L204: ='Revenue Segments'!AQ83 -> 0
B205: Mopeds | C205: ='Revenue Segments'!AH84 -> 0 | D205: ='Revenue Segments'!AI84 -> 0 | E205: ='Revenue Segments'!AJ84 -> 0 | F205: ='Revenue Segments'!AK84 -> 0 | G205: ='Revenue Segments'!AL84 -> 0 | H205: ='Revenue Segments'!AM84 -> 0 | I205: ='Revenue Segments'!AN84 -> 0 | J205: ='Revenue Segments'!AO84 -> 0 | ... L205: ='Revenue Segments'!AQ84 -> 0
B206: Three-wheelers | C206: ='Revenue Segments'!AH85 -> 0 | D206: ='Revenue Segments'!AI85 -> 0 | E206: ='Revenue Segments'!AJ85 -> 0 | F206: ='Revenue Segments'!AK85 -> 0 | G206: ='Revenue Segments'!AL85 -> 0 | H206: ='Revenue Segments'!AM85 -> 0 | I206: ='Revenue Segments'!AN85 -> 0 | J206: ='Revenue Segments'!AO85 -> 0 | ... L206: ='Revenue Segments'!AQ85 -> 0
B207: Revenue | C207: ='Income Statement'!AK70 -> 0 | D207: ='Income Statement'!AL70 -> 0 | E207: ='Income Statement'!AM70 -> 0 | F207: ='Income Statement'!AN70 -> 0 | G207: ='Income Statement'!AO70 -> 0 | H207: ='Income Statement'!AP70 -> 0 | I207: ='Income Statement'!AQ70 -> 0 | J207: ='Income Statement'!AR70 -> 80818.863 | ... L207: ='Income Statement'!AT70 -> 102412.09
B208: EBITDA | C208: ='Income Statement'!AK71 -> 0 | D208: ='Income Statement'!AL71 -> 0 | E208: ='Income Statement'!AM71 -> 0 | F208: ='Income Statement'!AN71 -> 0 | G208: ='Income Statement'!AO71 -> 0 | H208: ='Income Statement'!AP71 -> 0 | I208: ='Income Statement'!AQ71 -> 0 | J208: ='Income Statement'!AR71 -> 11395.46 | ... L208: ='Income Statement'!AT71 -> 14849.754
B209: EBITDA margin | C209: ='Income Statement'!AK72 -> 0 | D209: ='Income Statement'!AL72 -> 0 | E209: ='Income Statement'!AM72 -> 0 | F209: ='Income Statement'!AN72 -> 0 | G209: ='Income Statement'!AO72 -> 0 | H209: ='Income Statement'!AP72 -> 0 | I209: ='Income Statement'!AQ72 -> 0 | J209: ='Income Statement'!AR72 -> 0.141 | ... L209: ='Income Statement'!AT72 -> 0.145
B210: PAT | C210: ='Income Statement'!AK73 -> 0 | D210: ='Income Statement'!AL73 -> 0 | E210: ='Income Statement'!AM73 -> 0 | F210: ='Income Statement'!AN73 -> 0 | G210: ='Income Statement'!AO73 -> 0 | H210: ='Income Statement'!AP73 -> 0 | I210: ='Income Statement'!AQ73 -> 0 | J210: ='Income Statement'!AR73 -> 7381.2324 | ... L210: ='Income Statement'!AT73 -> 9631.3341
B211: EPS (₹) | C211: ='Income Statement'!AK74 -> 0 | D211: ='Income Statement'!AL74 -> 0 | E211: ='Income Statement'!AM74 -> 0 | F211: ='Income Statement'!AN74 -> 0 | G211: ='Income Statement'!AO74 -> 0 | H211: ='Income Statement'!AP74 -> 0 | I211: ='Income Statement'!AQ74 -> 0 | J211: ='Income Statement'!AR74 -> 155.36591 | ... L211: ='Income Statement'!AT74 -> 202.7278
B212: ROCE | C212: ='Income Statement'!AK75 -> 0 | D212: ='Income Statement'!AL75 -> 0 | E212: ='Income Statement'!AM75 -> 0 | F212: ='Income Statement'!AN75 -> 0 | G212: ='Income Statement'!AO75 -> 0 | H212: ='Income Statement'!AP75 -> 0 | I212: ='Income Statement'!AQ75 -> 0 | J212: ='Income Statement'!AR75 -> 0.33703329 | ... L212: ='Income Statement'!AT75 -> 0.29678391
B213: ROE | C213: ='Income Statement'!AK76 -> 0 | D213: ='Income Statement'!AL76 -> 0 | E213: ='Income Statement'!AM76 -> 0 | F213: ='Income Statement'!AN76 -> 0 | G213: ='Income Statement'!AO76 -> 0 | H213: ='Income Statement'!AP76 -> 0 | I213: ='Income Statement'!AQ76 -> 0 | J213: ='Income Statement'!AR76 -> 0.28022391 | ... L213: ='Income Statement'!AT76 -> 0.23751288
B214: Capital expenditure | C214: ='Balance Sheet'!C45 -> 728 | D214: ='Balance Sheet'!D45 -> 997 | E214: ='Balance Sheet'!E45 -> 1055 | F214: ='Balance Sheet'!F45 -> 1780 | G214: ='Balance Sheet'!G45 -> 1925 | H214: ='Balance Sheet'!H45 -> 2466.9749 | I214: ='Balance Sheet'!I45 -> 2798.1816 | J214: ='Balance Sheet'!J45 -> 3071.1168 | ... L214: ='Balance Sheet'!L45 -> 3584.4233
B215: Capex % of sales | C215: ='Balance Sheet'!C48 -> 0.035015151 | D215: ='Balance Sheet'!D48 -> 0.037796649 | E215: ='Balance Sheet'!E48 -> 0.033201158 | F215: ='Balance Sheet'!F48 -> 0.049102094 | G215: ='Balance Sheet'!G48 -> 0.040723503 | H215: ='Balance Sheet'!H48 -> 0.042 | I215: ='Balance Sheet'!I48 -> 0.04 | J215: ='Balance Sheet'!J48 -> 0.038 | ... L215: ='Balance Sheet'!L48 -> 0.035
B216: Depreciation | C216: ='Balance Sheet'!C46 -> 611 | D216: ='Balance Sheet'!D46 -> 631 | E216: ='Balance Sheet'!E46 -> 700 | F216: ='Balance Sheet'!F46 -> 748 | G216: ='Balance Sheet'!G46 -> 901 | H216: ='Balance Sheet'!H46 -> 842.27 | I216: ='Balance Sheet'!I46 -> 1042.9211 | J216: ='Balance Sheet'!J46 -> 1259.6957 | ... L216: ='Balance Sheet'!L46 -> 1707.0383
B217: Installed capacity (lakh) | C217: ='Revenue Segments'!E67/100000 -> 42 | D217: ='Revenue Segments'!H67/100000 -> 48 | E217: ='Revenue Segments'!K67/100000 -> 54 | F217: ='Revenue Segments'!N67/100000 -> 60 | G217: ='Revenue Segments'!Q67/100000 -> 66 | H217: ='Revenue Segments'!T67/100000 -> 74 | I217: ='Revenue Segments'!W67/100000 -> 84 | J217: ='Revenue Segments'!Z67/100000 -> 94 | K217: ='Revenue Segments'!AC67/100000 -> 103 | L217: ='Revenue Segments'!AF67/100000 -> 112
B218: Volume (lakh units) | C218: ='Revenue Segments'!AH86 -> 0 | D218: ='Revenue Segments'!AI86 -> 0 | E218: ='Revenue Segments'!AJ86 -> 0 | F218: ='Revenue Segments'!AK86 -> 0 | G218: ='Revenue Segments'!AL86 -> 0 | H218: ='Revenue Segments'!AM86 -> 0 | I218: ='Revenue Segments'!AN86 -> 0 | J218: ='Revenue Segments'!AO86 -> 0 | ... L218: ='Revenue Segments'!AQ86 -> 0
B219: Capacity utilisation | C219: ='Revenue Segments'!E68 -> 0.72880952 | D219: ='Revenue Segments'!H68 -> 0.765 | E219: ='Revenue Segments'!K68 -> 0.74611111 | F219: ='Revenue Segments'!N68 -> 0.76816667 | G219: ='Revenue Segments'!Q68 -> 0.85909091 | H219: ='Revenue Segments'!T68 -> 0.90135135 | I219: ='Revenue Segments'!W68 -> 0.90583643 | J219: ='Revenue Segments'!Z68 -> 0.90200883 | K219: ='Revenue Segments'!AC68 -> 0.90036807 | L219: ='Revenue Segments'!AF68 -> 0.89603305
B220: Inventory days | C220: ='Balance Sheet'!C36 -> 26 | D220: ='Balance Sheet'!D36 -> 23 | E220: ='Balance Sheet'!E36 -> 21 | F220: ='Balance Sheet'!F36 -> 24 | G220: ='Balance Sheet'!G36 -> 17 | H220: ='Balance Sheet'!H36 -> 17 | I220: ='Balance Sheet'!I36 -> 17 | J220: ='Balance Sheet'!J36 -> 17 | ... L220: ='Balance Sheet'!L36 -> 17
B221: Receivable days | C221: ='Balance Sheet'!C37 -> 17 | D221: ='Balance Sheet'!D37 -> 14 | E221: ='Balance Sheet'!E37 -> 15 | F221: ='Balance Sheet'!F37 -> 13 | G221: ='Balance Sheet'!G37 -> 16 | H221: ='Balance Sheet'!H37 -> 16 | I221: ='Balance Sheet'!I37 -> 16 | J221: ='Balance Sheet'!J37 -> 16 | ... L221: ='Balance Sheet'!L37 -> 16
B222: Payable days | C222: =-'Balance Sheet'!C38 -> -93 | D222: =-'Balance Sheet'!D38 -> -75 | E222: =-'Balance Sheet'!E38 -> -80 | F222: =-'Balance Sheet'!F38 -> -87 | G222: =-'Balance Sheet'!G38 -> -90 | H222: =-'Balance Sheet'!H38 -> -90 | I222: =-'Balance Sheet'!I38 -> -90 | J222: =-'Balance Sheet'!J38 -> -90 | ... L222: =-'Balance Sheet'!L38 -> -90
B223: Cash conversion cycle | C223: ='Balance Sheet'!C39 -> -50 | D223: ='Balance Sheet'!D39 -> -38 | E223: ='Balance Sheet'!E39 -> -44 | F223: ='Balance Sheet'!F39 -> -50 | G223: ='Balance Sheet'!G39 -> -57 | H223: ='Balance Sheet'!H39 -> -57 | I223: ='Balance Sheet'!I39 -> -57 | J223: ='Balance Sheet'!J39 -> -57 | ... L223: ='Balance Sheet'!L39 -> -57
B224: Operating cash flow | C224: ='Cash Flows'!C15 -> 1643 | D224: ='Cash Flows'!D15 -> 2057.3342 | E224: ='Cash Flows'!E15 -> 3484.4438 | F224: ='Cash Flows'!F15 -> 4314.9699 | G224: ='Cash Flows'!G15 -> 6279.3041 | H224: ='Cash Flows'!H15 -> 7262.6749 | I224: ='Cash Flows'!I15 -> 8604.4265 | J224: ='Cash Flows'!J15 -> 9926.3432 | ... L224: ='Cash Flows'!L15 -> 12624.554
B225: Free cash flow to firm | C225: ='Cash Flows'!C37 -> 879.00082 | D225: ='Cash Flows'!D37 -> 1050.1147 | E225: ='Cash Flows'!E37 -> 2421.1582 | F225: ='Cash Flows'!F37 -> 2492.8891 | G225: ='Cash Flows'!G37 -> 4282.0065 | H225: ='Cash Flows'!H37 -> 4727.2974 | I225: ='Cash Flows'!I37 -> 5737.8423 | J225: ='Cash Flows'!J37 -> 6786.8238 | ... L225: ='Cash Flows'!L37 -> 8971.7285
B226: Net debt / (cash) | C226: ='Balance Sheet'!C13-'Balance Sheet'!C27-'Balance Sheet'!C24 -> 447 | D226: ='Balance Sheet'!D13-'Balance Sheet'!D27-'Balance Sheet'!D24 -> 1179 | E226: ='Balance Sheet'!E13-'Balance Sheet'!E27-'Balance Sheet'!E24 -> 173 | F226: ='Balance Sheet'!F13-'Balance Sheet'!F27-'Balance Sheet'!F24 -> 274 | G226: ='Balance Sheet'!G13-'Balance Sheet'!G27-'Balance Sheet'!G24 -> 1236 | H226: ='Balance Sheet'!H13-'Balance Sheet'!H27-'Balance Sheet'!H24 -> -2451.1287 | I226: ='Balance Sheet'!I13-'Balance Sheet'!I27-'Balance Sheet'!I24 -> -6871.6809 | J226: ='Balance Sheet'!J13-'Balance Sheet'!J27-'Balance Sheet'!J24 -> -12048.334 | ... L226: ='Balance Sheet'!L13-'Balance Sheet'!L27-'Balance Sheet'!L24 -> -24724.638
B227: Net debt / EBITDA | C227: =C226/C208 -> #DIV/0! | D227: =D226/D208 -> #DIV/0! | E227: =E226/E208 -> #DIV/0! | F227: =F226/F208 -> #DIV/0! | G227: =G226/G208 -> #DIV/0! | H227: =H226/H208 -> #DIV/0! | I227: =I226/I208 -> #DIV/0! | J227: =J226/J208 -> -1.0572925 | ... L227: =L226/L208 -> -1.6649864
B228: Interest coverage (x) | C228: ='Income Statement'!E59 -> 15.571429 | D228: ='Income Statement'!H59 -> 18.971631 | E228: ='Income Statement'!K59 -> 19.302198 | F228: ='Income Statement'!N59 -> 32.107914 | G228: ='Income Statement'!Q59 -> 29.79902 | H228: ='Income Statement'!T59 -> 28.962155 | I228: ='Income Statement'!W59 -> 35.522671 | J228: ='Income Statement'!Z59 -> 41.931701 | K228: ='Income Statement'!AC59 -> 48.149652 | L228: ='Income Statement'!AF59 -> 54.642414
B229: Electric 2W volume (lakh) | C229: ='Revenue Segments'!E70/100000 -> 0.16 | D229: ='Revenue Segments'!H70/100000 -> 0.93 | E229: ='Revenue Segments'!K70/100000 -> 1.85 | F229: ='Revenue Segments'!N70/100000 -> 2.78 | G229: ='Revenue Segments'!Q70/100000 -> 3.7 | H229: ='Revenue Segments'!T70/100000 -> 6.29 | I229: ='Revenue Segments'!W70/100000 -> 9.1205 | J229: ='Revenue Segments'!Z70/100000 -> 12.03906 | K229: ='Revenue Segments'!AC70/100000 -> 15.048825 | L229: ='Revenue Segments'!AF70/100000 -> 18.05859
B230: EV share of 2W volume | C230: ='Revenue Segments'!E71 -> 0.00522705 | D230: ='Revenue Segments'!H71 -> 0.025326797 | E230: ='Revenue Segments'!K71 -> 0.045917101 | F230: ='Revenue Segments'!N71 -> 0.060316772 | G230: ='Revenue Segments'!Q71 -> 0.065255732 | H230: ='Revenue Segments'!T71 -> 0.094302849 | I230: ='Revenue Segments'!W71 -> 0.11986422 | J230: ='Revenue Segments'!Z71 -> 0.14198875 | K230: ='Revenue Segments'!AC71 -> 0.16227263 | L230: ='Revenue Segments'!AF71 -> 0.17994583
B231: Domestic revenue | C231: ='Revenue Segments'!AH88 -> 0 | D231: ='Revenue Segments'!AI88 -> 0 | E231: ='Revenue Segments'!AJ88 -> 0 | F231: ='Revenue Segments'!AK88 -> 0 | G231: ='Revenue Segments'!AL88 -> 0 | H231: ='Revenue Segments'!AM88 -> 0 | I231: ='Revenue Segments'!AN88 -> 0 | J231: ='Revenue Segments'!AO88 -> 0 | ... L231: ='Revenue Segments'!AQ88 -> 0
...

Sheet Guidance & Assumptions
B1: TVS MOTOR COMPANY LIMITED
B2: Fiscal year ending 31 March
B3: All amounts in ₹ crores unless stated · Central assumption register — every driver used downstream lives here
B5: A. MANAGEMENT GUIDANCE AND DISCLOSED OPERATING DATA
C6: FY2026A | D6: FY2027 guidance
B7: Total vehicle sales (lakh units) | C7: 58.89 | D7: 70–75 (implied)
B8: Two-wheeler volumes (lakh units) | C8: 56.7 | D8: —
B9: Electric 2W volumes (lakh units) | C9: 3.7 | D9: 6.0–6.5
B10: Total exports (lakh units) | C10: 15.85 | D10: —
B11: Export share of India 2W exports | C11: 0.275 | D11: —
B12: Operating EBITDA margin (standalone) | C12: 0.1286 | D12: 13.4%
B13: Installed 2W capacity (lakh units p.a.) | C13: 66 | D13: 74.0
B14: Effective tax rate | C14: 0.2628 | D14: 0.2517
B15: TVS Credit AUM (₹ cr) | C15: 30639 | D15: —
B16: TVS Motor holding in TVS Credit | C16: 0.8515 | D16: —
B18: B. MACRO AND INDUSTRY DRIVERS
C19: Input
B20: India 10-year G-Sec yield (risk-free rate) | C20: 0.0678
B21: India equity risk premium (total) | C21: 0.0708
B22: Long-run nominal GDP growth (terminal-growth ceiling) | C22: 0.095
B23: Domestic 2W industry volume growth, FY27–FY31 CAGR | C23: 0.08
B24: EV penetration of domestic 2W industry by FY31 | C24: 0.3
B25: USD/INR | C25: 88.5
B26: Steel / commodity basket inflation p.a. | C26: 0.03
B27: Share of raw-material inflation passed through in price | C27: ='Control Panel'!$C$78 -> 0.7
B29: C. OPERATING FORECAST DRIVERS (FY2027E – FY2031E)
C30: FY2027E | D30: FY2028E | E30: FY2029E | F30: FY2030E | G30: FY2031E
